[2024-06-30T20:06:02.805+0000] {local_task_job_runner.py:120} INFO - ::group::Pre task execution logs
[2024-06-30T20:06:02.912+0000] {taskinstance.py:2076} INFO - Dependencies all met for dep_context=non-requeueable deps ti=<TaskInstance: SparkETL.create_cluster manual__2024-06-30T20:05:35.931289+00:00 [queued]>
[2024-06-30T20:06:02.957+0000] {taskinstance.py:2076} INFO - Dependencies all met for dep_context=requeueable deps ti=<TaskInstance: SparkETL.create_cluster manual__2024-06-30T20:05:35.931289+00:00 [queued]>
[2024-06-30T20:06:02.960+0000] {taskinstance.py:2306} INFO - Starting attempt 1 of 6
[2024-06-30T20:06:03.129+0000] {taskinstance.py:2330} INFO - Executing <Task(DataprocCreateClusterOperator): create_cluster> on 2024-06-30 20:05:35.931289+00:00
[2024-06-30T20:06:03.158+0000] {warnings.py:112} WARNING - /home/***/.local/lib/python3.12/site-packages/***/task/task_runner/standard_task_runner.py:61: DeprecationWarning: This process (pid=83) is multi-threaded, use of fork() may lead to deadlocks in the child.
  pid = os.fork()

[2024-06-30T20:06:03.170+0000] {standard_task_runner.py:63} INFO - Started process 88 to run task
[2024-06-30T20:06:03.177+0000] {standard_task_runner.py:90} INFO - Running: ['***', 'tasks', 'run', 'SparkETL', 'create_cluster', 'manual__2024-06-30T20:05:35.931289+00:00', '--job-id', '4', '--raw', '--subdir', 'DAGS_FOLDER/PySparkETL.py', '--cfg-path', '/tmp/tmp9h9rykeo']
[2024-06-30T20:06:03.184+0000] {standard_task_runner.py:91} INFO - Job 4: Subtask create_cluster
[2024-06-30T20:06:03.505+0000] {task_command.py:426} INFO - Running <TaskInstance: SparkETL.create_cluster manual__2024-06-30T20:05:35.931289+00:00 [running]> on host 645e696cd5ce
[2024-06-30T20:06:04.054+0000] {taskinstance.py:2648} INFO - Exporting env vars: AIRFLOW_CTX_DAG_OWNER='Manikanta Bandham' AIRFLOW_CTX_DAG_ID='SparkETL' AIRFLOW_CTX_TASK_ID='create_cluster' AIRFLOW_CTX_EXECUTION_DATE='2024-06-30T20:05:35.931289+00:00' AIRFLOW_CTX_TRY_NUMBER='1' AIRFLOW_CTX_DAG_RUN_ID='manual__2024-06-30T20:05:35.931289+00:00'
[2024-06-30T20:06:04.063+0000] {taskinstance.py:430} INFO - ::endgroup::
[2024-06-30T20:06:04.066+0000] {dataproc.py:780} INFO - Creating cluster: udacitycluster
[2024-06-30T20:06:04.096+0000] {taskinstance.py:441} INFO - ::group::Post task execution logs
[2024-06-30T20:06:04.128+0000] {taskinstance.py:2905} ERROR - Task failed with exception
Traceback (most recent call last):
  File "/home/airflow/.local/lib/python3.12/site-packages/airflow/models/taskinstance.py", line 465, in _execute_task
    result = _execute_callable(context=context, **execute_callable_kwargs)
             ^^^^^^^^^^^^^^^^^^^^^^^^^^^^^^^^^^^^^^^^^^^^^^^^^^^^^^^^^^^^^
  File "/home/airflow/.local/lib/python3.12/site-packages/airflow/models/taskinstance.py", line 432, in _execute_callable
    return execute_callable(context=context, **execute_callable_kwargs)
           ^^^^^^^^^^^^^^^^^^^^^^^^^^^^^^^^^^^^^^^^^^^^^^^^^^^^^^^^^^^^
  File "/home/airflow/.local/lib/python3.12/site-packages/airflow/models/baseoperator.py", line 401, in wrapper
    return func(self, *args, **kwargs)
           ^^^^^^^^^^^^^^^^^^^^^^^^^^^
  File "/home/airflow/.local/lib/python3.12/site-packages/airflow/providers/google/cloud/operators/dataproc.py", line 781, in execute
    hook = DataprocHook(gcp_conn_id=self.gcp_conn_id, impersonation_chain=self.impersonation_chain)
           ^^^^^^^^^^^^^^^^^^^^^^^^^^^^^^^^^^^^^^^^^^^^^^^^^^^^^^^^^^^^^^^^^^^^^^^^^^^^^^^^^^^^^^^^
  File "/home/airflow/.local/lib/python3.12/site-packages/airflow/providers/google/cloud/hooks/dataproc.py", line 213, in __init__
    super().__init__(gcp_conn_id=gcp_conn_id, impersonation_chain=impersonation_chain)
  File "/home/airflow/.local/lib/python3.12/site-packages/airflow/providers/google/common/hooks/base_google.py", line 274, in __init__
    self.extras: dict = self.get_connection(self.gcp_conn_id).extra_dejson
                        ^^^^^^^^^^^^^^^^^^^^^^^^^^^^^^^^^^^^^
  File "/home/airflow/.local/lib/python3.12/site-packages/airflow/hooks/base.py", line 83, in get_connection
    conn = Connection.get_connection_from_secrets(conn_id)
           ^^^^^^^^^^^^^^^^^^^^^^^^^^^^^^^^^^^^^^^^^^^^^^^
  File "/home/airflow/.local/lib/python3.12/site-packages/airflow/models/connection.py", line 519, in get_connection_from_secrets
    raise AirflowNotFoundException(f"The conn_id `{conn_id}` isn't defined")
airflow.exceptions.AirflowNotFoundException: The conn_id `google_cloud_default` isn't defined
[2024-06-30T20:06:04.148+0000] {taskinstance.py:1206} INFO - Marking task as UP_FOR_RETRY. dag_id=SparkETL, task_id=create_cluster, run_id=manual__2024-06-30T20:05:35.931289+00:00, execution_date=20240630T200535, start_date=20240630T200602, end_date=20240630T200604
[2024-06-30T20:06:04.198+0000] {standard_task_runner.py:110} ERROR - Failed to execute job 4 for task create_cluster (The conn_id `google_cloud_default` isn't defined; 88)
[2024-06-30T20:06:04.245+0000] {local_task_job_runner.py:240} INFO - Task exited with return code 1
[2024-06-30T20:06:04.371+0000] {taskinstance.py:3503} INFO - 0 downstream tasks scheduled from follow-on schedule check
[2024-06-30T20:06:04.377+0000] {local_task_job_runner.py:222} INFO - ::endgroup::
